Workbook

Sheet Form Responses 1
A1: Timestamp | B1: PROGRAM | C1: SECTION | D1: Fullname Ex: Juan D. Cruz | E1: Name of Sender (Gcash) | F1: Reference No. of Payment | G1: Proof of Payment Upload here your screenshot as proof of payment. | H1: Gcash Number | I1: Column 8 | J1: Type number of keychain/s you want purchase and pay on June 18 after the Hooding Ceremony. | K1: Payment method | L1: Gcash Number | M1: Number | N1: Found in Gcash & Refunded 210 | O1: Not found in Gcash
A2: 45806.886 | B2: Bachelor of Science in Information Technology | C2: 4-IT1 | D2: John Paul Galido | E2: Lorie Erasga | F2: 00000000 | G2: https://drive.google.com/open?id=14fQzuzVx3BednIKmRUXookodJcud30yR
A3: 45808.573 | B3: Bachelor of Elementary Education (BEED) | C3: 4-EED2 | D3: LENNEL D. GRANDE | E3: ARNEL GRANDE | F3: 8029 211 774207 | G3: https://drive.google.com/open?id=1TcawMF3LlJ7C6v7gAlIv95QSJrl7-jmz | L3: 09305424246 | M3: 1
A4: 45809.533 | B4: Bachelor of Science in Information Technology | C4: 4 IT - 1 | D4: Danyca Alliah Villanueva | E4: Danyca Alliah Villanueva | F4: 6029244266398 | G4: https://drive.google.com/open?id=1cRelER2Xgs5jfif4YFr84iFPYJqaUsLB | L4: 09258471460 | M4: 1
A5: 45809.578 | B5: Bachelor of Science in Information Technology | C5: 4IT-4 | D5: Dianne T. Domingo | E5: Dianne Domingo | F5: 1029246322521 | G5: https://drive.google.com/open?id=1UbatZ5wGsBhPXbVwbQhNcOZatt0KBPAn | L5: 09955116313 | M5: 1
A6: 45809.609 | B6: Bachelor of Elementary Education (BEED) | C6: EED3 | D6: Mary Grace V. Lastre | E6: Mary Grace Lastre | F6: 0029247709648 | G6: https://drive.google.com/open?id=19U8DfOMyaNco4fU9_rPXy2TYDZPoErC4 | L6: 09667742796 | M6: 1
A7: 45809.989 | B7: Bachelor of Elementary Education (BEED) | C7: 4-Eed1 | D7: Fiona May Anne L. San Diego | E7: Fiona May Anne L. San Diego | F7: 1029264976605 | G7: https://drive.google.com/open?id=1QdQyTIShfgaJvcgloNv2UG5wBZ8IkcDX | L7: 09065558912 | M7: 1
A8: 45811.761 | B8: Bachelor of Secondary Education Major in English (BSED-E) | C8: 4-SEDE1 | D8: Chelo Mae B. Arrogante | E8: Chelo Mae Arrogante | F8: 9029315561063 | G8: https://drive.google.com/open?id=1uNNuBOxtoMYjufu8PGb-tYPNI-T9XaD- | M8: 1
A9: 45811.769 | B9: Bachelor of Secondary Education Major in English (BSED-E) | C9: 4-SEDE1 and 4-SEDE2 | D9: Sarah Joy Mangeron, Ingrid Montero, Chelo Mae Arrogante, Daphne June Durias, Dezerie Mae Amongan, Janna Marie Felias, Maxxieline Dela Cruz | E9: Maxxieline D. | F9: 1029321287492 | G9: https://drive.google.com/open?id=1zrc0IeZpZJutb-_FxqffZESnyWLUIal7 | M9: 7
A10: 45811.772 | B10: Bachelor of Secondary Education Major in English (BSED-E) | C10: 4-SEDE2 | D10: Jean Ivy G. Fresnido | E10: Jean Ivy Fresnido | F10: 5029 321 285188 | G10: https://drive.google.com/open?id=18ZpR4IbtU-DQOuQw7b6CyH3UyRpWAINK | M10: 1
A11: 45811.775 | B11: Bachelor of Secondary Education Major in English (BSED-E) | C11: 4-SEDE1 | D11: Cyril Del Valle | E11: Jamaica Banaticla | F11: 2029-321-484664 | G11: https://drive.google.com/open?id=1ZzWic2hxyDi2EkD1hUxMkXEKJtx1-Xte | M11: 1
A12: 45811.788 | B12: Bachelor of Secondary Education Major in English (BSED-E) | C12: 4-SEDE1 | D12: Sarah Joy H. Mangeron | E12: Sarah Joy M. | F12: 1029 313 458219 | G12: https://drive.google.com/open?id=1GV5mm8wcAslIF5uOCTzPm7_Lxx5A0xa9 | M12: 1
A13: 45811.79 | B13: Bachelor of Secondary Education Major in English (BSED-E) | C13: 4-SEDE2 | D13: Lhyn Marie P. Tabieros | E13: Lhyn Marie T | F13: 9029 322 399032 | G13: https://drive.google.com/open?id=1jOqW_cPskhH8CKW9XwaUOOh8urL9lcNM | M13: 1
A14: 45811.795 | B14: Bachelor of Secondary Education Major in English (BSED-E) | C14: 4SEDE1 | D14: Aubrey A. Pielago | E14: Mariesol B. | F14: 4029 322 666870 | G14: https://drive.google.com/open?id=1lQiq612rMURgpKgWVFq3P6Kn2WXPocRH | M14: 1
A15: 45811.804 | B15: Bachelor of Secondary Education Major in English (BSED-E) | C15: SEDE1 | D15: Jemelyn C. Desacula | E15: Juliana Marie C. Desacula | F15: 5029323126797 | G15: https://drive.google.com/open?id=10em77mRbSyHiEufzlTEvMgrmvG3Qi6fc | M15: 1
A16: 45811.81 | B16: Bachelor of Secondary Education Major in English (BSED-E) | C16: 4-SEDE1 | D16: Ingrid C. Montero | E16: Ma.Victoria Montero | F16: 7029315441811 | G16: https://drive.google.com/open?id=1mtuf9V_juxemr7HNVDfK8mRo-E-uwXlu | M16: 1
A17: 45811.826 | B17: Bachelor of Secondary Education Major in English (BSED-E) | C17: 4-SEDE2 | D17: Dezerie Mae L. Amongan | E17: Esperanza Amongan | F17: 5029 316 401888 | G17: https://drive.google.com/open?id=10qCvKcF8HW5MADvK2OEYtY9COQW3v4Qp | M17: 1
A18: 45811.86 | B18: Bachelor of Elementary Education (BEED) | C18: 4EED4 | D18: Robe Yuan P. Benito | E18: Lilibeth Benito | F18: 4029 325 981662 | G18: https://drive.google.com/open?id=11-T1a-VMI0tT-TPW_ZI0sH0udU25-gGr | M18: 1
A19: 45811.889 | B19: Bachelor of Secondary Education Major in English (BSED-E) | C19: 4SEDE-2 | D19: Arbie M. Crazo | E19: ARBIE C. | F19: 5029327375842 | G19: https://drive.google.com/open?id=1FcV50WNuXyvTESFlX7L1FLySBrWXyQ3D | M19: 1
A20: 45811.958 | B20: Bachelor of Secondary Education Major in English (BSED-E) | C20: SEDE—2 | D20: Mara Charisma A. Suarez | E20: John Edward Mayuga | F20: 2029 329 861078 | G20: https://drive.google.com/open?id=1OrmijUWeLBv6rFemA9ntZnj14V18DFu8 | M20: 1
A21: 45812.321 | B21: Bachelor of Science in Information Technology | C21: 4- IT1 | D21: Leah Marie M. Ferares | E21: Aberde Leo | F21: 0029 334 765119 | G21: https://drive.google.com/open?id=16M2bh30mvREy4nvP7TrIDE9Cg-piF6Tq | M21: 1
A22: 45812.379 | B22: Bachelor of Science in Information Technology | C22: 4-IT1 | D22: Jerome M. Lubrin | E22: JEROME L. | F22: 1029 336 504149 | G22: https://drive.google.com/open?id=1GK3aNDIuNMLOZ7BVfgzxKodxQcQCfH0D | M22: 1
A23: 45812.386 | B23: Bachelor of Science in Information Technology | C23: 4IT-1 | D23: Cristina S. Equial | E23: Cristina E. | F23: 1029336740245 | G23: https://drive.google.com/open?id=19L1Oj1qIbnQzaHvskLw2KIPpB0_ZuFjJ | M23: 1
A24: 45812.406 | B24: Bachelor of Science in Information Technology | C24: IV-IT1 | D24: Paul Ivan A. Arazo | E24: Paul Ivan A. Arazo | F24: 0029337486691 | G24: https://drive.google.com/open?id=10Xqy-HXUeQ5kzVvu-ZJhIvM4hHGRcJ8I | M24: 1
A25: 45812.408 | B25: Bachelor of Science in Accounting Information System | C25: 4-IT1 | D25: Anna Grace M. Rosco | E25: Anna Grace Rosco | F25: 1029 337 578059 | G25: https://drive.google.com/open?id=1q6tjWZHmvUAaQdn8dnhH_rblkXgOe5R8 | M25: 1
A26: 45812.422 | B26: Bachelor of Elementary Education (BEED) | C26: EED4 | D26: Justine A. Bandales | E26: Justine A. Bandales | F26: 7029 338 115436 | G26: https://drive.google.com/open?id=1rLNHKdhBdv1yTvwFHHFXODZQu_frrz5W | M26: 1
A27: 45812.424 | B27: Bachelor of Science in Computer Science | C27: 4-CS2 | D27: Lloyd Anthony Hontiveros | E27: Lloyd Anthony Hontiveros | F27: 5029 338 230120 | G27: https://drive.google.com/open?id=1W2m1y0z2eZSXObX6XL3RLb5OYu9ok-yq | M27: 1
A28: 45812.428 | B28: Bachelor of Secondary Education Major in English (BSED-E) | C28: 4-SEDE1 | D28: Kristine T. Oruga | E28: Kristine Oruga | F28: 4029 338 289102 | G28: https://drive.google.com/open?id=1egCZgI3Jd15h0h-psuwVcxPdx30gA6ax | M28: 1
A29: 45812.437 | B29: Bachelor of Secondary Education Major in English (BSED-E) | C29: 4-SEDE1 | D29: Tengco, Nixon D. | E29: Nixon Tengco | F29: 5029338794365 | G29: https://drive.google.com/open?id=1WJdxqeKkxG_9YOBdF1T3Gwb9TT2sV4mS | M29: 1
A30: 45812.448 | B30: Bachelor of Secondary Education Major in English (BSED-E) | C30: 4-SEDE1 | D30: Bernalet S. Matanguihan | E30: Jayvie Matanguihan | F30: 0029 339 223795 | G30: https://drive.google.com/open?id=1EqnGuQRgLWv_DcGQI9WjjYmL4fVGyNyJ | M30: 1
A31: 45812.462 | B31: Bachelor of Science in Accountancy | C31: A6 | D31: Mary Jane S. Arcansalin | E31: Mary Jane Arcansalin | F31: 0029339819752 | G31: https://drive.google.com/open?id=1N0jIasobyJRK10gM3i-XWS_aS1IKmC4T | M31: 1
A32: 45812.483 | B32: Bachelor of Science in Computer Science | C32: 4-cs3 | D32: Judy Anne S. Ortile | E32: Judy Anne S. Ortile | F32: 8029340710172 | G32: https://drive.google.com/open?id=1hHXMgChHrwO6HfxkXek1SQDvBfwRf77i | M32: 1
A33: 45812.509 | B33: Bachelor of Science in Accountancy | C33: 4-A3 | D33: Charisse Mae R. Cardiño | E33: Charisse Mae Cardiño | F33: 9029341831221 | G33: https://drive.google.com/open?id=1KSYrOOY4zVDyYchfjl21mpa9FEugXFgU | M33: 1
A34: 45812.585 | B34: Bachelor of Secondary Education Major in English (BSED-E) | C34: 4SEDE 1 | D34: Glamirose U. Napiza | E34: Glamirose Napiza | F34: 9029344997487 | M34: 1
A35: 45812.59 | B35: Bachelor of Secondary Education Major in Science (BSED-S) | C35: 4SEDS-2 | D35: Shyla Marie M. Buseta | E35: Shyla Marie M. Buseta | F35: 7029345333604 | G35: https://drive.google.com/open?id=1TU180I7XuHKhnSDTDQiMgpiituZT9bXr | M35: 1
A36: 45812.6 | B36: Bachelor of Science in Accountancy | C36: 4-A3 | D36: Mariel Joy M. Mayor | E36: Mariel Joy Mayor | F36: 6029345708791 | G36: https://drive.google.com/open?id=11AtJk9KnYXNR5KmBPJZJU8GSUozSxGEM | M36: 1
A37: 45812.61 | B37: Bachelor of Science in Accountancy | C37: 4-A4 | D37: Pauline B. Tingzon | E37: Pauline Tingzon | F37: 6029346142477 | G37: https://drive.google.com/open?id=1_5TAGkZkeksHvgBJcqNngINV1CBOe_kY | M37: 1
A38: 45812.623 | B38: Bachelor of Science in Accountancy | C38: 4-A6 | D38: Bernadette R. Arboleda | E38: Bernadette Arboleda | F38: 7029346693403 | G38: https://drive.google.com/open?id=1kFxDAB0Bhvn6OS58_xD9PaFulZ_tGiNv | M38: 1
A39: 45812.718 | B39: Bachelor of Elementary Education (BEED) | C39: Eed2 | D39: Jackie N. Carandang | E39: Jackie N. Carandang | F39: 8029350742467 | G39: https://drive.google.com/open?id=1R2m97vjM5VRgKTSp45TtDAvlDEipcX1W | M39: 1
A40: 45812.753 | B40: Bachelor of Elementary Education (BEED) | C40: 4-EED1 | D40: Michael C. Valenzuela | E40: John Arman P. Baldonado | F40: 2029352578573 | G40: https://drive.google.com/open?id=1TW1hD0sqh-8uXMRQiGCyx6y05nozki49 | M40: 1
...

Sheet Order Total
A2: gcash | B2: PROGRAM | C2: NUMBER OF ORDERS | E2: overall | F2: PROGRAM | G2: NUMBER OF ORDERS
B3: Bachelor of Elementary Education (BEED) | C3: =SUMIF('Form Responses 1'!B:M,B3,'Form Responses 1'!M:M) -> 34 | F3: Bachelor of Elementary Education (BEED) | G3: =C3+C14 -> 96
B4: Bachelor of Secondary Education Major in English (BSED-E) | C4: =SUMIF('Form Responses 1'!B:M,B4,'Form Responses 1'!M:M) -> 39 | F4: Bachelor of Secondary Education Major in English (BSED-E) | G4: =C4+C15 -> 53
B5: Bachelor of Secondary Education Major in Science (BSED-S) | C5: =SUMIF('Form Responses 1'!B:M,B5,'Form Responses 1'!M:M) -> 5 | F5: Bachelor of Secondary Education Major in Science (BSED-S) | G5: =C5+C16 -> 23
B6: Bachelor of Secondary Education Major in Mathematics (BSED-M) | C6: =SUMIF('Form Responses 1'!B:M,B6,'Form Responses 1'!M:M) -> 2 | F6: Bachelor of Secondary Education Major in Mathematics (BSED-M) | G6: =C6+C17 -> 7
B7: Bachelor of Science in Accountancy | C7: =SUMIF('Form Responses 1'!B:M,B7,'Form Responses 1'!M:M) -> 14 | F7: Bachelor of Science in Accountancy | G7: =C7+C18 -> 48
B8: Bachelor of Science in Accounting Information System | C8: =SUMIF('Form Responses 1'!B:M,B8,'Form Responses 1'!M:M) -> 3 | F8: Bachelor of Science in Accounting Information System | G8: =C8+C19 -> 9
B9: Bachelor of Science in Information Technology | C9: =SUMIF('Form Responses 1'!B:M,B9,'Form Responses 1'!M:M) -> 28 | F9: Bachelor of Science in Information Technology | G9: =C9+C20 -> 45
B10: Bachelor of Science in Computer Science | C10: =SUMIF('Form Responses 1'!B:M,B10,'Form Responses 1'!M:M) -> 10 | F10: Bachelor of Science in Computer Science | G10: =C10+C21 -> 12
B11: OVERALL TOTAL | C11: =SUM(C3:C10) -> 135 | F11: OVERALL TOTAL | G11: =SUM(G3:G10) -> 293
A13: cash | B13: PROGRAM | C13: NUMBER OF ORDERS
B14: Bachelor of Elementary Education (BEED) | C14: =SUMIF('Form Responses 1'!B:M,B14,'Form Responses 1'!J:J) -> 62
B15: Bachelor of Secondary Education Major in English (BSED-E) | C15: =SUMIF('Form Responses 1'!B:M,B15,'Form Responses 1'!J:J) -> 14
B16: Bachelor of Secondary Education Major in Science (BSED-S) | C16: =SUMIF('Form Responses 1'!B:M,B16,'Form Responses 1'!J:J) -> 18
B17: Bachelor of Secondary Education Major in Mathematics (BSED-M) | C17: =SUMIF('Form Responses 1'!B:M,B17,'Form Responses 1'!J:J) -> 5
B18: Bachelor of Science in Accountancy | C18: =SUMIF('Form Responses 1'!B:M,B18,'Form Responses 1'!J:J) -> 34
B19: Bachelor of Science in Accounting Information System | C19: =SUMIF('Form Responses 1'!B:M,B19,'Form Responses 1'!J:J) -> 6
B20: Bachelor of Science in Information Technology | C20: =SUMIF('Form Responses 1'!B:M,B20,'Form Responses 1'!J:J) -> 17
B21: Bachelor of Science in Computer Science | C21: =SUMIF('Form Responses 1'!B:M,B21,'Form Responses 1'!J:J) -> 2
B22: OVERALL TOTAL | C22: =SUM(C14:C21) -> 158

Sheet SCF
B3: STATEMENT OF CASH FLOWS
B5: Incoming Payments | D5: =(260*5)+(50*(sum('Form Responses 1'!M:M))) -> 8050
B6: Refunds due to Price Change | D6: =(-210)*5 -> -1050
B7: Gcash received for Pre-Payment | E7: =SUM(D5:D6) -> 7000
B8: Cash to be received in June 18 | E8: =50*(SUM('Form Responses 1'!J:J)) -> 7900
B9: TOTAL AMOUNT | E9: =SUM(E8,E7) -> 14900
B11: Keychain Cost | C11: =1990*2+(1194)+995 -> 6169
B12: Bundle Deal Discount | C12: =-((90*2)+30+60) -> -270
B13: Payment Discount (ShopeePay) | C13: =-8*4 -> -32
B14: Shopee Voucher | C14: =-(400+400+250+215) -> -1265
B15: Shipping Fee | C15: =40*4 -> 160
B16: Shipping Discount | C16: =-40*4 -> -160 | D16: =SUM(C11:C16) -> 4602
B18: Transfer Costs
B19: Gcash to ShopeePay | C19: =15*2 -> 30
D20: =sum(C19:C20) -> 30 | E20: =sum(D16:D20) -> 4632 | F20: =E7-E20 -> 2368 | G20: =C80 -> 2351 | H20: =G20-F20 -> -17
B21: Gross Profit | E21: =E9-E20 -> 10268
D23: 1215 | E23: =E21/D23 -> 8.4510288
D24: PRICE | E24: # OF TRASH BINS
B60: ShopeePay balance
B61: Gcash to ShopeePay | D61: =726+15+3899 -> 4640
B62: Transfer Fee | D62: =-15*2 -> -30
B63: Received in ShopeePay | D63: =sum(D61:D62) -> 4610
B65: Payments
B66: Receipt 1 | C66: 876
B67: Receipt 2 | C67: 1492
B68: Receipt 3 | C68: 1492
B69: Receipt 4 | C69: =752-8 -> 744 | D69: =sum(C66:C70) -> 4604
B71: Remaining balance to be added to GCash Balance | D71: =D63-D69 -> 6
B73: GCash Balance
B74: Payment Received (net of refunds) | C74: =E7 -> 7000
B75: Gcash to ShopeePay | C75: =-3884-741 -> -4625
B76: Transfer Fee | C76: =D62 -> -30
B78: Remaining GCash after payment | C78: =SUM(C74:C76) -> 2345
B79: Add back: ShopeePay (sobra) | C79: =D71 -> 6
B80: Total Amount Remaining in GCash | C80: =C78+C79 -> 2351
